Workbook

Sheet Claims data summary
A3: Average of Gross claim amount
A4: 578102.35
A9: Average of Gross inflation adjusted claim
A10: 630996.72
A14: Avg claim amount by year
A15: Row Labels | B15: Average of Gross inflation adjusted claim
A16: 2018 | B16: 643510.46
A17: 2019 | B17: 607077.47
A18: 2020 | B18: 600236.35
A19: 2021 | B19: 596316.91
A20: 2022 | B20: 881240.57
A21: 2023 | B21: 464505.99
A22: Grand Total | B22: 630996.72
A24: Claim summary
A25: Net claims incurred by claim type
A26: Row Labels | B26: Sum of Net inflation adjusted claim
A27: Cargo Liability | B27: 10604640
A28: Collision Liability | B28: 11495061
A29: Damage to Other Vessels | B29: 11944680
A30: Environmental Pollution | B30: 18039390
A31: Injury to Third Parties | B31: 7892047.8
A32: Grand Total | B32: 59975820
A35: Claim count by claim type
A36: Row Labels | B36: Count of Claim ID
A37: Cargo Liability | B37: 19
A38: Collision Liability | B38: 21
A39: Damage to Other Vessels | B39: 20
A40: Environmental Pollution | B40: 22
A41: Injury to Third Parties | B41: 18
A42: Grand Total | B42: 100
A45: Avg claim cost by claim type
A46: Row Labels | B46: Average of Gross claim amount
A47: Cargo Liability | B47: 543964.6
A48: Collision Liability | B48: 517298.51
A49: Damage to Other Vessels | B49: 576540.58
A50: Environmental Pollution | B50: 790953.47
A51: Injury to Third Parties | B51: 426658.36
A52: Grand Total | B52: 578102.35
A54: Cause of loss summary
A55: Net claims incurred by cause of loss
...

Sheet Claims Data
A1: Claim ID | B1: Date of Claim | C1: Type of Claim | D1: Claim Incurred ($) | E1: Claim Status | F1: Gross claim amount | G1: Policy Limits ($) | H1: Deductible ($) | I1: Cause of Loss | J1: Location | K1: Insured Party | L1: Gross Tonnage | M1: Prior Claims History | N1: Inflation Index | O1: Gross inflation adjusted claim | P1: Net inflation adjusted claim | Q1: Capped net adjusted incurred claim | R1: Attritional claim flag - (set equal to 1 if claim is less than 1m, otherwise 0) | S1: Year
A2: CLM-00001 | B2: 43664 | C2: Collision Liability | D2: 737423.28 | E2: Closed | F2: =$D2 -> 737423.28 | G2: 5000000 | H2: 12345.92 | I2: Human Error | J2: Indian Ocean | K2: Company 9 | L2: =IF(C2="Cargo Liability",RANDBETWEEN(10000,80000),IF(C2="Collision Liability",RANDBETWEEN(20000,100000),IF(C2="Environmental Pollution",RANDBETWEEN(50000,120000),IF(C2="Damage to Other Vessels",RANDBETWEEN(15000,90000),IF(C2="Injury to Third Parties",RANDBETWEEN(5000,60000)))))) -> 37418 | M2: 4 | N2: =IF(YEAR(B2)=2023, 1.03, IF(YEAR(B2)=2022, 1.0506, IF(YEAR(B2)=2021, 1.071612, IF(YEAR(B2)=2020, 1.10376036, IF(YEAR(B2)=2019, 1.1479107744, IF(YEAR(B2)=2018, 1.20530631312, 1)))))) -> 1.1479108 | O2: =$F2*$N2 -> 846496.13 | P2: =($F2-$H2)*$N2 -> 832324.11 | Q2: =MIN($P2, $G2) -> 832324.11 | R2: =IF(Q2<1000000,1,0) -> 1 | S2: =YEAR(B2) -> 2019
A3: CLM-00002 | B3: 43978 | C3: Cargo Liability | D3: 315189.74 | E3: Closed | F3: =$D3 -> 315189.74 | G3: 5000000 | H3: 33716.76 | I3: Technical Failure | J3: Atlantic Ocean | K3: Company 4 | L3: =IF(C3="Cargo Liability",RANDBETWEEN(10000,80000),IF(C3="Collision Liability",RANDBETWEEN(20000,100000),IF(C3="Environmental Pollution",RANDBETWEEN(50000,120000),IF(C3="Damage to Other Vessels",RANDBETWEEN(15000,90000),IF(C3="Injury to Third Parties",RANDBETWEEN(5000,60000)))))) -> 67678 | M3: 6 | N3: =IF(YEAR(B3)=2023, 1.03, IF(YEAR(B3)=2022, 1.0506, IF(YEAR(B3)=2021, 1.071612, IF(YEAR(B3)=2020, 1.10376036, IF(YEAR(B3)=2019, 1.1479107744, IF(YEAR(B3)=2018, 1.20530631312, 1)))))) -> 1.1037604 | O3: =$F3*$N3 -> 347893.94 | P3: =($F3-$H3)*$N3 -> 310678.72 | Q3: =MIN($P3, $G3) -> 310678.72 | R3: =IF(Q3<1000000,1,0) -> 1 | S3: =YEAR(B3) -> 2020
A4: CLM-00003 | B4: 43427 | C4: Damage to Other Vessels | D4: 678364.99 | E4: Closed | F4: =$D4 -> 678364.99 | G4: 5000000 | H4: 34396.91 | I4: Criminal Activity | J4: Mediterranean Sea | K4: Company 2 | L4: =IF(C4="Cargo Liability",RANDBETWEEN(10000,80000),IF(C4="Collision Liability",RANDBETWEEN(20000,100000),IF(C4="Environmental Pollution",RANDBETWEEN(50000,120000),IF(C4="Damage to Other Vessels",RANDBETWEEN(15000,90000),IF(C4="Injury to Third Parties",RANDBETWEEN(5000,60000)))))) -> 34514 | M4: 3 | N4: =IF(YEAR(B4)=2023, 1.03, IF(YEAR(B4)=2022, 1.0506, IF(YEAR(B4)=2021, 1.071612, IF(YEAR(B4)=2020, 1.10376036, IF(YEAR(B4)=2019, 1.1479107744, IF(YEAR(B4)=2018, 1.20530631312, 1)))))) -> 1.2053063 | O4: =$F4*$N4 -> 817637.61 | P4: =($F4-$H4)*$N4 -> 776178.79 | Q4: =MIN($P4, $G4) -> 776178.79 | R4: =IF(Q4<1000000,1,0) -> 1 | S4: =YEAR(B4) -> 2018
A5: CLM-00004 | B5: 44201 | C5: Environmental Pollution | D5: 203840.58 | E5: Open | F5: =$D5 -> 203840.58 | G5: 5000000 | H5: 11703.88 | I5: Natural Disaster | J5: Pacific Ocean | K5: Company 17 | L5: =IF(C5="Cargo Liability",RANDBETWEEN(10000,80000),IF(C5="Collision Liability",RANDBETWEEN(20000,100000),IF(C5="Environmental Pollution",RANDBETWEEN(50000,120000),IF(C5="Damage to Other Vessels",RANDBETWEEN(15000,90000),IF(C5="Injury to Third Parties",RANDBETWEEN(5000,60000)))))) -> 51495 | M5: 7 | N5: =IF(YEAR(B5)=2023, 1.03, IF(YEAR(B5)=2022, 1.0506, IF(YEAR(B5)=2021, 1.071612, IF(YEAR(B5)=2020, 1.10376036, IF(YEAR(B5)=2019, 1.1479107744, IF(YEAR(B5)=2018, 1.20530631312, 1)))))) -> 1.071612 | O5: =$F5*$N5 -> 218438.01 | P5: =($F5-$H5)*$N5 -> 205895.99 | Q5: =MIN($P5, $G5) -> 205895.99 | R5: =IF(Q5<1000000,1,0) -> 1 | S5: =YEAR(B5) -> 2021
A6: CLM-00005 | B6: 45091 | C6: Injury to Third Parties | D6: 98692.46 | E6: In Litigation | F6: =$D6 -> 98692.46 | G6: 1000000 | H6: 48127.72 | I6: Human Error | J6: Indian Ocean | K6: Company 12 | L6: =IF(C6="Cargo Liability",RANDBETWEEN(10000,80000),IF(C6="Collision Liability",RANDBETWEEN(20000,100000),IF(C6="Environmental Pollution",RANDBETWEEN(50000,120000),IF(C6="Damage to Other Vessels",RANDBETWEEN(15000,90000),IF(C6="Injury to Third Parties",RANDBETWEEN(5000,60000)))))) -> 35177 | M6: 8 | N6: =IF(YEAR(B6)=2023, 1.03, IF(YEAR(B6)=2022, 1.0506, IF(YEAR(B6)=2021, 1.071612, IF(YEAR(B6)=2020, 1.10376036, IF(YEAR(B6)=2019, 1.1479107744, IF(YEAR(B6)=2018, 1.20530631312, 1)))))) -> 1.03 | O6: =$F6*$N6 -> 101653.23 | P6: =($F6-$H6)*$N6 -> 52081.682 | Q6: =MIN($P6, $G6) -> 52081.682 | R6: =IF(Q6<1000000,1,0) -> 1 | S6: =YEAR(B6) -> 2023
A7: CLM-00006 | B7: 43584 | C7: Collision Liability | D7: 243918.65 | E7: Closed | F7: =$D7 -> 243918.65 | G7: 5000000 | H7: 10585.54 | I7: Technical Failure | J7: Atlantic Ocean | K7: Company 3 | L7: =IF(C7="Cargo Liability",RANDBETWEEN(10000,80000),IF(C7="Collision Liability",RANDBETWEEN(20000,100000),IF(C7="Environmental Pollution",RANDBETWEEN(50000,120000),IF(C7="Damage to Other Vessels",RANDBETWEEN(15000,90000),IF(C7="Injury to Third Parties",RANDBETWEEN(5000,60000)))))) -> 45404 | M7: 2 | N7: =IF(YEAR(B7)=2023, 1.03, IF(YEAR(B7)=2022, 1.0506, IF(YEAR(B7)=2021, 1.071612, IF(YEAR(B7)=2020, 1.10376036, IF(YEAR(B7)=2019, 1.1479107744, IF(YEAR(B7)=2018, 1.20530631312, 1)))))) -> 1.1479108 | O7: =$F7*$N7 -> 279996.85 | P7: =($F7-$H7)*$N7 -> 267845.59 | Q7: =MIN($P7, $G7) -> 267845.59 | R7: =IF(Q7<1000000,1,0) -> 1 | S7: =YEAR(B7) -> 2019
A8: CLM-00007 | B8: 44398 | C8: Environmental Pollution | D8: 765873.46 | E8: Closed | F8: =$D8 -> 765873.46 | G8: 5000000 | H8: 17345.37 | I8: Natural Disaster | J8: North Sea | K8: Company 11 | L8: =IF(C8="Cargo Liability",RANDBETWEEN(10000,80000),IF(C8="Collision Liability",RANDBETWEEN(20000,100000),IF(C8="Environmental Pollution",RANDBETWEEN(50000,120000),IF(C8="Damage to Other Vessels",RANDBETWEEN(15000,90000),IF(C8="Injury to Third Parties",RANDBETWEEN(5000,60000)))))) -> 115092 | M8: 1 | N8: =IF(YEAR(B8)=2023, 1.03, IF(YEAR(B8)=2022, 1.0506, IF(YEAR(B8)=2021, 1.071612, IF(YEAR(B8)=2020, 1.10376036, IF(YEAR(B8)=2019, 1.1479107744, IF(YEAR(B8)=2018, 1.20530631312, 1)))))) -> 1.071612 | O8: =$F8*$N8 -> 820719.19 | P8: =($F8-$H8)*$N8 -> 802131.68 | Q8: =MIN($P8, $G8) -> 802131.68 | R8: =IF(Q8<1000000,1,0) -> 1 | S8: =YEAR(B8) -> 2021
A9: CLM-00008 | B9: 44638 | C9: Damage to Other Vessels | D9: 913843.77 | E9: Closed | F9: =$D9 -> 913843.77 | G9: 5000000 | H9: 25600.34 | I9: Criminal Activity | J9: Atlantic Ocean | K9: Company 5 | L9: =IF(C9="Cargo Liability",RANDBETWEEN(10000,80000),IF(C9="Collision Liability",RANDBETWEEN(20000,100000),IF(C9="Environmental Pollution",RANDBETWEEN(50000,120000),IF(C9="Damage to Other Vessels",RANDBETWEEN(15000,90000),IF(C9="Injury to Third Parties",RANDBETWEEN(5000,60000)))))) -> 42631 | M9: 0 | N9: =IF(YEAR(B9)=2023, 1.03, IF(YEAR(B9)=2022, 1.0506, IF(YEAR(B9)=2021, 1.071612, IF(YEAR(B9)=2020, 1.10376036, IF(YEAR(B9)=2019, 1.1479107744, IF(YEAR(B9)=2018, 1.20530631312, 1)))))) -> 1.0506 | O9: =$F9*$N9 -> 960084.26 | P9: =($F9-$H9)*$N9 -> 933188.55 | Q9: =MIN($P9, $G9) -> 933188.55 | R9: =IF(Q9<1000000,1,0) -> 1 | S9: =YEAR(B9) -> 2022
A10: CLM-00009 | B10: 44150 | C10: Cargo Liability | D10: 754890.21 | E10: Closed | F10: =$D10 -> 754890.21 | G10: 5000000 | H10: 38184.44 | I10: Technical Failure | J10: Mediterranean Sea | K10: Company 8 | L10: =IF(C10="Cargo Liability",RANDBETWEEN(10000,80000),IF(C10="Collision Liability",RANDBETWEEN(20000,100000),IF(C10="Environmental Pollution",RANDBETWEEN(50000,120000),IF(C10="Damage to Other Vessels",RANDBETWEEN(15000,90000),IF(C10="Injury to Third Parties",RANDBETWEEN(5000,60000)))))) -> 57118 | M10: 6 | N10: =IF(YEAR(B10)=2023, 1.03, IF(YEAR(B10)=2022, 1.0506, IF(YEAR(B10)=2021, 1.071612, IF(YEAR(B10)=2020, 1.10376036, IF(YEAR(B10)=2019, 1.1479107744, IF(YEAR(B10)=2018, 1.20530631312, 1)))))) -> 1.1037604 | O10: =$F10*$N10 -> 833217.89 | P10: =($F10-$H10)*$N10 -> 791071.42 | Q10: =MIN($P10, $G10) -> 791071.42 | R10: =IF(Q10<1000000,1,0) -> 1 | S10: =YEAR(B10) -> 2020
A11: CLM-00010 | B11: 43258 | C11: Collision Liability | D11: 600293.27 | E11: Open | F11: =$D11 -> 600293.27 | G11: 5000000 | H11: 1143.25 | I11: Human Error | J11: Atlantic Ocean | K11: Company 10 | L11: =IF(C11="Cargo Liability",RANDBETWEEN(10000,80000),IF(C11="Collision Liability",RANDBETWEEN(20000,100000),IF(C11="Environmental Pollution",RANDBETWEEN(50000,120000),IF(C11="Damage to Other Vessels",RANDBETWEEN(15000,90000),IF(C11="Injury to Third Parties",RANDBETWEEN(5000,60000)))))) -> 45500 | M11: 5 | N11: =IF(YEAR(B11)=2023, 1.03, IF(YEAR(B11)=2022, 1.0506, IF(YEAR(B11)=2021, 1.071612, IF(YEAR(B11)=2020, 1.10376036, IF(YEAR(B11)=2019, 1.1479107744, IF(YEAR(B11)=2018, 1.20530631312, 1)))))) -> 1.2053063 | O11: =$F11*$N11 -> 723537.27 | P11: =($F11-$H11)*$N11 -> 722159.3 | Q11: =MIN($P11, $G11) -> 722159.3 | R11: =IF(Q11<1000000,1,0) -> 1 | S11: =YEAR(B11) -> 2018
A12: CLM-00011 | B12: 44251 | C12: Environmental Pollution | D12: 320726.12 | E12: Closed | F12: =$D12 -> 320726.12 | G12: 5000000 | H12: 42318.97 | I12: Technical Failure | J12: North Sea | K12: Company 7 | L12: =IF(C12="Cargo Liability",RANDBETWEEN(10000,80000),IF(C12="Collision Liability",RANDBETWEEN(20000,100000),IF(C12="Environmental Pollution",RANDBETWEEN(50000,120000),IF(C12="Damage to Other Vessels",RANDBETWEEN(15000,90000),IF(C12="Injury to Third Parties",RANDBETWEEN(5000,60000)))))) -> 109854 | M12: 7 | N12: =IF(YEAR(B12)=2023, 1.03, IF(YEAR(B12)=2022, 1.0506, IF(YEAR(B12)=2021, 1.071612, IF(YEAR(B12)=2020, 1.10376036, IF(YEAR(B12)=2019, 1.1479107744, IF(YEAR(B12)=2018, 1.20530631312, 1)))))) -> 1.071612 | O12: =$F12*$N12 -> 343693.96 | P12: =($F12-$H12)*$N12 -> 298344.44 | Q12: =MIN($P12, $G12) -> 298344.44 | R12: =IF(Q12<1000000,1,0) -> 1 | S12: =YEAR(B12) -> 2021
A13: CLM-00012 | B13: 44180 | C13: Cargo Liability | D13: 195238.55 | E13: Closed | F13: =$D13 -> 195238.55 | G13: 1000000 | H13: 25634.69 | I13: Criminal Activity | J13: Mediterranean Sea | K13: Company 6 | L13: =IF(C13="Cargo Liability",RANDBETWEEN(10000,80000),IF(C13="Collision Liability",RANDBETWEEN(20000,100000),IF(C13="Environmental Pollution",RANDBETWEEN(50000,120000),IF(C13="Damage to Other Vessels",RANDBETWEEN(15000,90000),IF(C13="Injury to Third Parties",RANDBETWEEN(5000,60000)))))) -> 73863 | M13: 8 | N13: =IF(YEAR(B13)=2023, 1.03, IF(YEAR(B13)=2022, 1.0506, IF(YEAR(B13)=2021, 1.071612, IF(YEAR(B13)=2020, 1.10376036, IF(YEAR(B13)=2019, 1.1479107744, IF(YEAR(B13)=2018, 1.20530631312, 1)))))) -> 1.1037604 | O13: =$F13*$N13 -> 215496.57 | P13: =($F13-$H13)*$N13 -> 187202.02 | Q13: =MIN($P13, $G13) -> 187202.02 | R13: =IF(Q13<1000000,1,0) -> 1 | S13: =YEAR(B13) -> 2020
... A101: CLM-00100 | B101: 44922 | C101: Environmental Pollution | D101: 5000000 | E101: In Litigation | F101: =$D101 -> 5000000 | G101: 10000000 | H101: 18723.79 | I101: Natural Disaster | J101: Atlantic Ocean | K101: Company 15 | L101: =IF(C101="Cargo Liability",RANDBETWEEN(10000,80000),IF(C101="Collision Liability",RANDBETWEEN(20000,100000),IF(C101="Environmental Pollution",RANDBETWEEN(50000,120000),IF(C101="Damage to Other Vessels",RANDBETWEEN(15000,90000),IF(C101="Injury to Third Parties",RANDBETWEEN(5000,60000)))))) -> 55548 | M101: 9 | N101: =IF(YEAR(B101)=2023, 1.03, IF(YEAR(B101)=2022, 1.0506, IF(YEAR(B101)=2021, 1.071612, IF(YEAR(B101)=2020, 1.10376036, IF(YEAR(B101)=2019, 1.1479107744, IF(YEAR(B101)=2018, 1.20530631312, 1)))))) -> 1.0506 | O101: =$F101*$N101 -> 5253000 | P101: =($F101-$H101)*$N101 -> 5233328.8 | Q101: =MIN($P101, $G101) -> 5233328.8 | R101: =IF(Q101<1000000,1,0) -> 0 | S101: =YEAR(B101) -> 2022

Sheet Pure Premium Work
G1: Claim frequency per gross tonnage
B2: Inflation Indices (Assumed for the Purpose of This Exercise): | G2: 1 | H2: Calculate the Loss Frequency using a pivot table, make sure to remove the large loss event. Claim frequency = Number of Claims/Gross Tonnage for all exposure.
D4: (1 + annual inflation) | E4: Inflation index | G4: Year | H4: Gross tonnage for all exposure | I4: No of claims | J4: Claim frequency per unit of gross tonnage
B5: 2018 | C5: 1.08 (8% inflation) | D5: 1.08 | E5: =E6*D6 -> 1.2053063 | G5: 2018 | H5: =C15 -> 45000000 | I5: ='Claims data summary'!$B85 -> 10 | J5: =$I5/$H5 -> 2.2222222e-07
B6: 2019 | C6: 1.05 (5% inflation) | D6: 1.05 | E6: =E7*D7 -> 1.1479108 | G6: =G5+1 -> 2019 | H6: =C16 -> 49000000 | I6: ='Claims data summary'!$B86 -> 17 | J6: =$I6/$H6 -> 3.4693878e-07
B7: 2020 | C7: 1.04 (4% inflation) | D7: 1.04 | E7: =E8*D8 -> 1.1037604 | G7: =G6+1 -> 2020 | H7: =C17 -> 41750000 | I7: ='Claims data summary'!$B87 -> 20 | J7: =$I7/$H7 -> 4.7904192e-07
B8: 2021 | C8: 1.03 (3% inflation) | D8: 1.03 | E8: =E9*D9 -> 1.071612 | G8: =G7+1 -> 2021 | H8: =C18 -> 41500000 | I8: ='Claims data summary'!$B88 -> 20 | J8: =$I8/$H8 -> 4.8192771e-07
B9: 2022 | C9: 1.02 (2% inflation) | D9: 1.02 | E9: =E10*D10 -> 1.0506 | G9: =G8+1 -> 2022 | H9: =C19 -> 43590000 | I9: ='Claims data summary'!$B89 -> 17 | J9: =$I9/$H9 -> 3.8999771e-07
B10: 2023 | C10: 1.02 (2% inflation) | D10: 1.02 | E10: =E11*D11 -> 1.03 | G10: =G9+1 -> 2023 | H10: =C20 -> 44750000 | I10: ='Claims data summary'!$B90 -> 16 | J10: =$I10/$H10 -> 3.575419e-07
B11: 2024 | C11: 1.03 (3% expected over year) | D11: 1.03 | E11: 1
G12: Claim severity analysis (average cost per claim)
B13: Exposure information for the account provided by client | G13: 2 | H13: Calculate the Average cost per claim (Loss Severity) using a pivot table, make sure to remove the large loss event. Instructions: Create a pivot table with Year, Sum of Capped net inflation adjusted incurred claim and Count of Claim ID. Loss Severity= Sum of Capped net inflation adjusted incurred claim / Count of Claim ID for each year.
B14: Year | C14: Gross tonnage
B15: 2018 | C15: =45000000 -> 45000000
B16: =B15+1 -> 2019 | C16: 49000000
B17: =B16+1 -> 2020 | C17: 41750000 | G17: ='Claims data summary'!C95/'Claims data summary'!$B95 -> 616787.65
B18: =B17+1 -> 2021 | C18: 41500000 | G18: ='Claims data summary'!C96/'Claims data summary'!$B96 -> 574361.93
B19: =B18+1 -> 2022 | C19: 43590000 | G19: ='Claims data summary'!C97/'Claims data summary'!$B97 -> 563794.47
B20: =B19+1 -> 2023 | C20: 44750000 | G20: ='Claims data summary'!C98/'Claims data summary'!$B98 -> 566396.68
G21: =('Claims data summary'!C99-5000000)/'Claims data summary'!$B99 -> 557084.75
B22: 2024 expected gross tonnage provided by client | C22: 40000000 | G22: ='Claims data summary'!C100/'Claims data summary'!$B100 -> 434932.88
C24: Given Assumptions
B25: 1 | C25: Commission is 0%
B26: 2 | C26: No adjustment is required for claims development patters
B27: 3 | C27: Deductibles in the upcoming policy period will be the same as deductible in prior policy periods. | G27: Loss cost calculation
B28: 4 | C28: Individual policies run from 1/1 - 31/12 each year | G28: 3 | H28: Complete the table below using the values derived in steps 1 and 2. HINT: Expected loss is the product of claim frequency and average claim severity.
B29: 5 | C29: Assume a large loss is any loss >$1m incurred
B30: 6 | C30: Assume the large loss event is a 1-in-20 year event. | G30: Loss cost | H30: Average cost per claim (Loss Severity) | I30: Claim frequency per unit of gross tonnage | J30: Expected loss per unit of gross tonnage
B31: 7 | C31: Assume expenses are 30% of the loss cost. | G31: 2018 | H31: =$G17 -> 616787.65 | I31: =$J5 -> 2.2222222e-07 | J31: =$H31*$I31 -> 0.13706392
B32: 8 | C32: Assume a 10% profit requirement on this account in calculating the premium | G32: 2019 | H32: =$G18 -> 574361.93 | I32: =$J6 -> 3.4693878e-07 | J32: =$H32*$I32 -> 0.19926843
G33: 2020 | H33: =$G19 -> 563794.47 | I33: =$J7 -> 4.7904192e-07 | J33: =$H33*$I33 -> 0.27008118
G34: 2021 | H34: =$G20 -> 566396.68 | I34: =$J8 -> 4.8192771e-07 | J34: =$H34*$I34 -> 0.27296225
G35: 2022 | H35: =$G21 -> 557084.75 | I35: =$J9 -> 3.8999771e-07 | J35: =$H35*$I35 -> 0.21726177
G36: 2023 | H36: =$G22 -> 434932.88 | I36: =$J10 -> 3.575419e-07 | J36: =$H36*$I36 -> 0.15550673
A37: 5 | B37: Identify the Large Loss Event adjusted for inflation.
B38: Large Loss Event | G38: 4 | H38: Calculate the following using the values derived in step 3.
B39: {='Claims Data'!O101} -> 5253000
A41: 6 | B41: Derive an appropriate Return Period. (Consider the information provided in the "Given Assumptions"). | G41: Average frequency per unit exposure | H41: =AVERAGE(I31:I36) -> 3.7961171e-07
B42: Return Period | G42: Average severity per claim | H42: =AVERAGE(H31:H36) -> 552226.39
B43: =1/(1/20) -> 20
...

Sheet Report
